Workbook
Name CauseList: '_lists<Do Not Edit>'!$A$1:$A$10

Sheet ReadMe
A1: Reconciliation Template — How to Use
A3: Goal: | B3: Verify that your Income Statement, Balance Sheet, and Cash Flow Statement are consistent and tie out.
A5: What to do: | B5: 1) Open your modeling workbook. 2) In each Final tab (IS_Final, BS_Final, CF_Final), copy the requested figures for the same three fiscal years into the yellow input cells on the Reconcile_Inputs sheet. 3) Review the PASS/CHECK results on Reconcile_Checks. 4) If anything is flagged, log it on Issues_Log and fix at the source.
A8: Color legend: | B8: Yellow = paste your inputs Gray = calculated Green/Red = PASS/CHECK results
A10: Tip | B10: Work oldest to latest year (left to right). Confirm units ($ in millions vs thousands) first.

Sheet Glossary
A1: Glossary – Reconciliation Terms
A4: Term in Template | B4: Full Form / Meaning | C4: Notes
A5: BEGIN | B5: Beginning of Period | C5: Value at the start of the reporting period (e.g., Dec 31, 2022 if reporting 2023 figures).
A6: END | B6: End of Period | C6: Value at the end of the reporting period (e.g., Dec 31, 2023 if reporting 2023 figures).
A7: IS | B7: Income Statement | C7: The company’s performance report showing revenue, expenses, and profit for a period.
A8: CF | B8: Cash Flow Statement | C8: The statement showing how cash moved in and out of the business during a period.
A9: BS | B9: Balance Sheet | C9: A snapshot of the company’s assets, liabilities, and equity at a specific date.
A12: Cash Tie-Out
A13: Term in Template | B13: Full Form / Meaning | C13: Notes
A14: BS: Cash & Cash Equivalents — END | B14: Cash on hand and highly liquid investments at period end | C14: Compare BS and CF figures to ensure tie-out.
A15: CF: Cash & Cash Equivalents — END | B15: Same as above, from CF statement | C15: Should match BS cash exactly.
A18: Net Income Tie-Out
A19: Term in Template | B19: Full Form / Meaning | C19: Notes
A20: IS: Net Income | B20: Profit after all expenses, interest, and taxes | C20: From the IS; also called “Net earnings” or “Net profit.”
A21: CF (OCF): Net Income (as reported) | B21: Net income as reported in the Operating section of the CF statement | C21: Should match IS net income exactly.
A24: Working Capital Bridge
A25: Term in Template | B25: Full Form / Meaning | C25: Notes
A26: Accounts Receivable — END / BEGIN | B26: Amount owed by customers for goods/services delivered | C26: Found in BS under Current Assets.
A27: Accounts Payable — END / BEGIN | B27: Amount owed to suppliers/vendors for goods/services received | C27: Found in BS under Current Liabilities.
A28: Deferred Revenue — END / BEGIN | B28: Payments received for goods/services not yet delivered | C28: A liability; decreases as services are delivered.
A29: Other Current Assets — END / BEGIN | B29: All other short-term assets not listed separately | C29: Often includes prepaid expenses, short-term deposits.
A30: Other Current Liabilities — END / BEGIN | B30: All other short-term liabilities not listed separately | C30: Often includes accrued expenses and tax payables.
A31: Inventory — END / BEGIN (if any) | B31: Goods held for sale | C31: Rare for pure software companies.
A32: CF (OCF): Change in operating assets & liabilities (reported) | B32: Net working capital movement as reported in the CF statement | C32: Can include FX and acquisition effects.
A33: Adjustments – WC in Acquisitions | B33: Working capital changes from buying another business | C33: Disclosed in notes; remove from your core NWC bridge.
A34: Adjustments – FX Impact on WC | B34: Currency translation effects on working capital | C34: Disclosed in notes; remove from your core NWC bridge.
A37: PP&E Rollforward
A38: Term in Template | B38: Full Form / Meaning | C38: Notes
A39: PP&E, net — BEGIN / END | B39: Property, Plant & Equipment after accumulated depreciation | C39: From BS under long-term assets.
A40: CF (Investing): Capital expenditures (CapEx) | B40: Cash outflows to buy or upgrade PP&E | C40: Shown in CF Investing section.
A41: Depreciation & Amortization expense (D&A) | B41: Non-cash expense; reduces PP&E value over time | C41: From IS or CF.
A42: Proceeds from asset sales / disposals | B42: Cash inflows from selling PP&E | C42: From CF Investing section.
A43: Non-cash PP&E adjustments | B43: Leases, impairments, FX translation adjustments to PP&E | C43: Disclosed in notes.
A46: Debt Rollforward
A47: Term in Template | B47: Full Form / Meaning | C47: Notes
A48: Total Debt — BEGIN / END | B48: Sum of short-term and long-term borrowings | C48: From BS liabilities.
A49: CF (Financing): Debt issued | B49: New borrowings (cash inflow) | C49: From CF Financing section.
A50: CF (Financing): Debt repaid | B50: Loan repayments (cash outflow) | C50: From CF Financing section.
A51: Adjustments: FX / Non-cash debt movements | B51: Currency impacts or debt changes not involving cash | C51: Disclosed in notes.
A54: Retained Earnings Rollforward
...

Sheet Reconcile_Inputs
A1: Paste the SAME three fiscal years across all sections
A3: Line
B4: 2025 | C4: 2024 | D4: 2023
A5: Core Tie-Out Figures
A6: IS: Net Income | B6: -9119 | C6: -429536 | D6: -181792
A7: CF (OCF): Net Income (as reported) | B7: -9119 | C7: -429536 | D7: -181792
A8: BS: Cash & Cash Equivalents — END of period | B8: 227649 | C8: 287996 | D8: 295402
A9: CF: Cash & Cash Equivalents — END of period | B9: 227649 | C9: 287996 | D9: 295402
A10: Working Capital (Balance Sheet)
A11: Accounts Receivable — END | B11: 264565 | C11: 166731 | D11: 0
A12: Accounts Receivable — BEGIN | B12: 166731 | C12: 0 | D12: 0
A13: Accounts Payable — END | B13: 7519 | C13: 1738 | D13: 0
A14: Accounts Payable — BEGIN | B14: 1738 | C14: 0 | D14: 0
A15: Deferred Revenue — END | B15: 468968 | C15: 362142 | D15: 0
A16: Deferred Revenue — BEGIN | B16: 362142 | C16: 0 | D16: 0
A17: Other Current Assets — END | B17: 79375 | C17: 81443 | D17: 0
A18: Other Current Assets — BEGIN | B18: 81443 | C18: 0 | D18: 0
A19: Other Current Liabilities — END | B19: 94913 | C19: 337071 | D19: 0
A20: Other Current Liabilities — BEGIN | B20: 337071 | C20: 0 | D20: 0
A21: Inventory — END (if any) | B21: 0 | C21: 0 | D21: 0
A22: Inventory — BEGIN (if any) | B22: 0 | C22: 0 | D22: 0
... A25: Adjustments: FX/translation impact on working capital (if disclosed) | B25: 0 | C25: 0 | D25: 0
A26: PP&E Rollforward
A27: PP&E, net — BEGIN | B27: 2954 | C27: 0 | D27: 0
A28: PP&E, net — END | B28: 4013 | C28: 2954 | D28: 0
A29: CF (Investing): Capital expenditures (CapEx) — cash outflow | B29: -3765 | C29: -1596 | D29: -6070
A30: Depreciation & Amortization expense (from IS or CF) | B30: 10986 | C30: 6535 | D30: 5593
A31: Proceeds from asset sales / disposals (Investing, if any) | B31: 0 | C31: 0 | D31: -9620
A32: Non-cash PP&E adjustments (leases, FX, impairments if disclosed) | B32: 0 | C32: 0 | D32: 0
A33: Debt Rollforward
A34: Total Debt — BEGIN (short + long-term) | B34: 0 | C34: 0 | D34: 0
A35: Total Debt — END (short + long-term) | B35: 0 | C35: 0 | D35: 0
A36: CF (Financing): Debt issued — cash inflow | B36: 0 | C36: 0 | D36: 0
A37: CF (Financing): Debt repaid — cash outflow | B37: 0 | C37: 0 | D37: 0
A38: Adjustments: FX / Non-cash debt movements (if disclosed) | B38: 0 | C38: 0 | D38: 0
A39: Equity & Retained Earnings
A40: Retained Earnings — BEGIN | B40: -1161288 | C40: 0 | D40: 0
A41: Retained Earnings — END | B41: -1170407 | C41: -429536 | D41: -181792
A42: Dividends paid (CF Financing; often zero for software) | B42: 0 | C42: 0 | D42: 0
A43: Other Comprehensive Income (OCI) for the year (from Statement of Equity) | B43: -8508 | C43: 2398 | D43: 0
...

Sheet Reconcile_Checks
A1: Automated Checks (PASS means your statements tie out for that check/year)
A3: Check
B4: 2025 | C4: 2024 | D4: 2023 | E4: 2025 (FY-3) Status | F4: 2024 (FY-2) Status | G4: 2023 (FY-1) Status
A5: Cash tie-out: BS ending cash MINUS CF ending cash (should be 0) | B5: =Reconcile_Inputs!B8 - Reconcile_Inputs!B9 -> 0 | C5: =Reconcile_Inputs!C8 - Reconcile_Inputs!C9 -> 0 | D5: =Reconcile_Inputs!D8 - Reconcile_Inputs!D9 -> 0 | E5: =IF(ABS(B5)<=0.5,"PASS","CHECK") -> PASS | F5: =IF(ABS(C5)<=0.5,"PASS","CHECK") -> PASS | G5: =IF(ABS(D5)<=0.5,"PASS","CHECK") -> PASS
A6: Net income tie-out: IS MINUS CF OCF net income (should be 0) | B6: =Reconcile_Inputs!B6 - Reconcile_Inputs!B7 -> 0 | C6: =Reconcile_Inputs!C6 - Reconcile_Inputs!C7 -> 0 | D6: =Reconcile_Inputs!D6 - Reconcile_Inputs!D7 -> 0 | E6: =IF(ABS(B6)<=0.5,"PASS","CHECK") -> PASS | F6: =IF(ABS(C6)<=0.5,"PASS","CHECK") -> PASS | G6: =IF(ABS(D6)<=0.5,"PASS","CHECK") -> PASS
A7: Working capital bridge: (Reported CF change in OA&L) MINUS (computed -ΔNWC adjusted) (should be 0 ± rounding) | B7: =Reconcile_Inputs!B23 - (-((Reconcile_Inputs!B11 - Reconcile_Inputs!B12) + (Reconcile_Inputs!B17 - Reconcile_Inputs!B18) + (Reconcile_Inputs!B21 - Reconcile_Inputs!B22) - (Reconcile_Inputs!B13 - Reconcile_Inputs!B14) - (Reconcile_Inputs!B15 - Reconcile_Inputs!B16) - (Reconcile_Inputs!B19 - Reconcile_Inputs!B20)) - Reconcile_Inputs!B24 - Reconcile_Inputs!B25) -> -66369 | C7: =Reconcile_Inputs!C23 - (-((Reconcile_Inputs!C11 - Reconcile_Inputs!C12) + (Reconcile_Inputs!C17 - Reconcile_Inputs!C18) + (Reconcile_Inputs!C21 - Reconcile_Inputs!C22) - (Reconcile_Inputs!C13 - Reconcile_Inputs!C14) - (Reconcile_Inputs!C15 - Reconcile_Inputs!C16) - (Reconcile_Inputs!C19 - Reconcile_Inputs!C20)) - Reconcile_Inputs!C24 - Reconcile_Inputs!C25) -> -210444 | D7: =Reconcile_Inputs!D23 - (-((Reconcile_Inputs!D11 - Reconcile_Inputs!D12) + (Reconcile_Inputs!D17 - Reconcile_Inputs!D18) + (Reconcile_Inputs!D21 - Reconcile_Inputs!D22) - (Reconcile_Inputs!D13 - Reconcile_Inputs!D14) - (Reconcile_Inputs!D15 - Reconcile_Inputs!D16) - (Reconcile_Inputs!D19 - Reconcile_Inputs!D20)) - Reconcile_Inputs!D24 - Reconcile_Inputs!D25) -> -43518 | E7: =IF(ABS(B7)<=0.5,"PASS","CHECK") -> CHECK | F7: =IF(ABS(C7)<=0.5,"PASS","CHECK") -> CHECK | G7: =IF(ABS(D7)<=0.5,"PASS","CHECK") -> CHECK | M7: GitLab’s 10-K only provides Balance Sheet data for FY2025 and FY2024. FY2023 Balance Sheet values are not disclosed. For reconciliation purposes, FY2023 Balance Sheet ‘BEGIN’ values are set to zero, and working capital / PP&E rollforwards for FY2023 and FY2024 should be interpreted as non-applicable. This does not affect modeling going forward.
A8: PP&E rollforward: Expected END (Begin - CapEx - D&A + Disposals + Non-cash) MINUS BS END (should be 0 ± rounding) | B8: =(Reconcile_Inputs!B27 + ( -1 * Reconcile_Inputs!B29 ) - Reconcile_Inputs!B30 + Reconcile_Inputs!B31 + Reconcile_Inputs!B32) - Reconcile_Inputs!B28 -> -8280 | C8: =(Reconcile_Inputs!C27 + ( -1 * Reconcile_Inputs!C29 ) - Reconcile_Inputs!C30 + Reconcile_Inputs!C31 + Reconcile_Inputs!C32) - Reconcile_Inputs!C28 -> -7893 | D8: =(Reconcile_Inputs!D27 + ( -1 * Reconcile_Inputs!D29 ) - Reconcile_Inputs!D30 + Reconcile_Inputs!D31 + Reconcile_Inputs!D32) - Reconcile_Inputs!D28 -> -9143 | E8: =IF(ABS(B8)<=0.5,"PASS","CHECK") -> CHECK | F8: =IF(ABS(C8)<=0.5,"PASS","CHECK") -> CHECK | G8: =IF(ABS(D8)<=0.5,"PASS","CHECK") -> CHECK
A9: Debt rollforward: Expected END (Begin + Issued - Repaid + Adj) MINUS BS END (should be 0 ± rounding) | B9: =(Reconcile_Inputs!B34 + Reconcile_Inputs!B36 - Reconcile_Inputs!B37 + Reconcile_Inputs!B38) - Reconcile_Inputs!B35 -> 0 | C9: =(Reconcile_Inputs!C34 + Reconcile_Inputs!C36 - Reconcile_Inputs!C37 + Reconcile_Inputs!C38) - Reconcile_Inputs!C35 -> 0 | D9: =(Reconcile_Inputs!D34 + Reconcile_Inputs!D36 - Reconcile_Inputs!D37 + Reconcile_Inputs!D38) - Reconcile_Inputs!D35 -> 0 | E9: =IF(ABS(B9)<=0.5,"PASS","CHECK") -> PASS | F9: =IF(ABS(C9)<=0.5,"PASS","CHECK") -> PASS | G9: =IF(ABS(D9)<=0.5,"PASS","CHECK") -> PASS
A10: Retained earnings rollforward: Expected END (Begin + NI - Dividends + Prior adj) MINUS BS END (should be 0 ± rounding) | B10: =(Reconcile_Inputs!B40 + Reconcile_Inputs!B6 - Reconcile_Inputs!B42 + Reconcile_Inputs!B44) - Reconcile_Inputs!B41 -> 0 | C10: =(C40 + C6 - C42 + C44) - C41 -> 0 | D10: =(D40 + D6 - D42 + D44) - D41 -> 0 | E10: =IF(ABS(B10)<=0.5,"PASS","CHECK") -> PASS | F10: =IF(ABS(C10)<=0.5,"PASS","CHECK") -> PASS | G10: =IF(ABS(D10)<=0.5,"PASS","CHECK") -> PASS

Sheet Issues_Log
A1: Test Name | B1: Year | C1: Symptom (what failed) | D1: Likely Cause | E1: Action Taken | F1: Resolved?
A2: Core Tie-Out Figures | B2: ALL | C2: Incorrect Net Income numbers (potentially calculation errors in original Income Statement sheet) | D2: Wrong category / mapping | E2: Needed to take Net Income number from "Net loss attributable to GitLab" from IS_Raw, not the Net Income number on IS_Raw, since that is the true net income attributable to GitLab common stockholders. | F2: YES
A3: Core Tie-Out Figures | B3: ALL | C3: Incorrect Balance Sheet Cash & Cash Equivalents numbers (potentially calculation errors in original Balance Sheet | D3: Wrong category / mapping | E3: "Short-Term Investments" was wrongly included under "Cash & Cash Equivalents" in the original Cash Flow Statement. "Short-Term Investments" was changed to being under "Other Current Assets". | F3: YES
A4: Core Tie-Out Figures | B4: ALL | C4: Missing Cash Flow Statement Cash & Cash Equivalents numbers (potentially calculation errors in original Cash Flow Statement) | D4: Copy/paste error | E4: Due to a page break in the original 10-K PDF, the section containing the Cash & Cash Equivalents line items was not typed into the CF_Raw worksheet. This section was typed in and checked to reconcile the issue. | F4: YES
A5: Working Capital (Balance Sheet) | B5: ALL | C5: Final numbers not tying out. | D5: Restricted cash causing tie-out issue | E5: GitLab’s 10-K only provides Balance Sheet data for FY2025 and FY2024. FY2023 Balance Sheet values are not disclosed. For reconciliation purposes, FY2023 Balance Sheet ‘BEGIN’ values are set to zero, and working capital / PP&E rollforwards for FY2023 and FY2024 should be interpreted as non-applicable. This does not affect modeling going forward. | F5: NO
A6: Working Capital (Balance Sheet) | B6: 2025 | C6: Typing error (79.375 instead of 79,375) | D6: Copy/paste error | E6: Fixed typing error. | F6: YES
A7: Working Capital (Balance Sheet) | B7: ALL | C7: Was not sure if adjustments: WC acquired in business combinations was disclosed or not | D7: Non-cash item misinterpreted | E7: Set to 0 since GitLab Inc. disclosed none. | F7: YES
A8: Working Capital (Balance Sheet) | B8: ALL | C8: Was not sure if adjustments: FX impact on working capital was disclosed or not | D8: Non-cash item misinterpreted | E8: Set to 0 since GitLab Inc. disclosed none. | F8: YES
A9: PP&E Rollforward | B9: ALL | C9: Final numbers not tying out. | D9: Restricted cash causing tie-out issue | E9: GitLab’s 10-K only provides Balance Sheet data for FY2025 and FY2024. FY2023 Balance Sheet values are not disclosed. For reconciliation purposes, FY2023 Balance Sheet ‘BEGIN’ values are set to zero, and working capital / PP&E rollforwards for FY2023 and FY2024 should be interpreted as non-applicable. This does not affect modeling going forward. | F9: NO
A10: PP&E Rollforward | B10: ALL | C10: Was not sure if there were any non-cash PP&E adjustments | D10: Non-cash item misinterpreted | E10: Set to 0 since GitLab Inc. disclosed none. | F10: YES
A11: Equity & Retained Earnings Rollforward | B11: ALL | C11: Was not sure if there were any prior-period adjustments/restatements | D11: Non-cash item misinterpreted | E11: Set to 0 since GitLab Inc. disclosed none. | F11: YES
A12: Equity & Retained Earnings Rollforward | C12: Final number not tying out. | D12: Wrong category / mapping | E12: Updated numbers to refect usage of the "Net loss atrributable to GitHub" Net Income number, not the Net Income number on IS_Raw | F12: YES

Sheet _lists<Do Not Edit>
A1: Units mismatch (000s vs millions)
A2: Period mismatch (TTM vs FY)
A3: Sign flipped (+/-)
A4: Double-counted subtotal
A5: Wrong category / mapping
A6: Acquisition effects not adjusted
A7: FX/translation not captured
A8: Restricted cash causing tie-out issue
A9: Non-cash item misinterpreted
A10: Copy/paste error
